<?xml version="1.0"?>
<!--
  Dog2 Robot Description (Xacro Source)
  
  Recreated from correct URDF file
  Date: 2026-01-27
  
  INERTIA CORRECTIONS:
  - Leg 1 & 2: Positive X (front legs)
  - Leg 3 & 4: Negative X (rear legs, mirrored geometry)
-->
<robot xmlns:xacro="http://www.ros.org/wiki/xacro" name="dog2">

  <xacro:arg name="controllers_yaml" default="$(find dog2_description)/config/ros2_controllers.yaml"/>
  <xacro:property name="controllers_yaml" value="$(arg controllers_yaml)"/>

  <!-- Joint limits -->
  <xacro:property name="hip_lower_limit" value="-2.618"/>
  <xacro:property name="hip_upper_limit" value="2.618"/>
  <xacro:property name="hip_effort" value="50"/>
  <xacro:property name="hip_velocity" value="20"/>
  <xacro:property name="knee_lower_limit" value="-2.8"/>
  <xacro:property name="knee_upper_limit" value="2.8"/>
  <xacro:property name="knee_effort" value="50"/>
  <xacro:property name="knee_velocity" value="20"/>
  <xacro:property name="prismatic_effort" value="100"/>
  <xacro:property name="prismatic_velocity" value="5"/>

  <!-- Shared angle constants -->
  <xacro:property name="PI_CONST" value="3.141592653589793"/>
  <xacro:property name="half_pi" value="1.5707963267948966"/>

  <!-- 左右腿镜像：rail / 右侧髋关节 / 右侧膝几何 由常量表达，单腿仅保留必要不对称（如 hip_xyz、大腿 mesh 翻转）。 -->
  <xacro:property name="leg_rail_rpy_L" value="${half_pi} 0 0"/>
  <xacro:property name="leg_rail_rpy_R" value="${half_pi} 0 ${-PI_CONST}"/>
  <!-- Local rail axis: chosen so R_rail * axis = base_link +X for +q slide (left vs right mirror). -->
  <xacro:property name="leg_rail_axis_L" value="1 0 0"/>
  <xacro:property name="leg_rail_axis_R" value="-1 0 0"/>
  <xacro:property name="leg_hip_rpy_R" value="${PI_CONST} 0 ${half_pi}"/>
  <xacro:property name="leg_knee_xyz_R" value="-0.0233 -0.055 -0.0254"/>
  <xacro:property name="leg_thigh_mesh_flip_rpy" value="0 ${PI_CONST} 0"/>

  <!-- Joint passive dynamics (simulation stabilization) -->
  <xacro:property name="prismatic_damping" value="0.25"/>
  <xacro:property name="prismatic_friction" value="0.05"/>
  <xacro:property name="hip_damping" value="0.12"/>
  <xacro:property name="hip_friction" value="0.02"/>
  <xacro:property name="knee_damping" value="0.15"/>
  <xacro:property name="knee_friction" value="0.02"/>

  <!-- Contact model (conservative baseline for stability) -->
  <xacro:property name="foot_contact_mu1" value="1.0"/>
  <xacro:property name="foot_contact_mu2" value="1.0"/>
  <xacro:property name="foot_contact_kp" value="2.0e4"/>
  <xacro:property name="foot_contact_kd" value="20.0"/>
  <xacro:property name="foot_contact_min_depth" value="0.0005"/>
  <xacro:property name="foot_contact_max_vel" value="0.2"/>

  <!-- Inertia properties -->
  <xacro:property name="leg12_thigh_xyz" value="0.026 -0.0760041259902766 0.0649874821212071"/>
  <xacro:property name="leg12_shin_xyz" value="0.0254901816398352 -0.143524743603395 -0.0694046953395906"/>
  <xacro:property name="leg3_thigh_xyz" value="-0.0259999999999999 -0.0760041259902766 0.0649874821212069"/>
  <xacro:property name="leg3_shin_xyz" value="-0.0265098183601649 -0.143524743603395 -0.0694046953395908"/>
  <xacro:property name="leg4_thigh_xyz" value="-0.026 -0.0760041259902766 0.0649874821212069"/>
  <xacro:property name="leg4_shin_xyz" value="-0.0265089672547710 -0.1429895138560395 -0.0691152554666486"/>

  <!--
    foot_tip_xyz (tibia_link frame): *_foot_fixed / 绿色调试球心位置（回退前工作区基准）。
    YZ: L3 沿胫骨在 YZ 平面内方向；X: 向机身横向收拢（foot_tip_lateral_inboard_m）。
    Y: +半直径（+r）后再沿 −tibia Y 平移 1.5×直径（=3r）；Z: foot_tip_z_down_m；与 leg_parameters 一致。
  -->
  <xacro:property name="foot_sphere_radius" value="0.012"/>
  <xacro:property name="foot_tip_plus_y_half_diameter_m" value="${foot_sphere_radius}"/>
  <xacro:property name="foot_tip_minus_y_one_and_half_diameter_m" value="${3 * foot_sphere_radius}"/>
  <xacro:property name="foot_tip_lateral_inboard_m" value="0.024"/>
  <xacro:property name="foot_tip_z_down_m" value="0.012"/>
  <xacro:property name="leg12_foot_tip_xyz" value="${foot_tip_lateral_inboard_m} ${foot_tip_plus_y_half_diameter_m - foot_tip_minus_y_one_and_half_diameter_m - 0.269179} -0.142168"/>
  <xacro:property name="leg3_foot_tip_xyz" value="-${foot_tip_lateral_inboard_m} ${foot_tip_plus_y_half_diameter_m - foot_tip_minus_y_one_and_half_diameter_m - 0.269179} -0.142168"/>
  <xacro:property name="leg4_foot_tip_xyz" value="-${foot_tip_lateral_inboard_m} ${foot_tip_plus_y_half_diameter_m - foot_tip_minus_y_one_and_half_diameter_m - 0.269202} -0.142121"/>

  <!-- World and base -->
  <link name="base_footprint"/>

  <!--
    Semantic base placement (current source-of-truth)
    ============================================================
    Historical urdf_shift_* bookkeeping has been removed. The fixed transform
    from base_footprint to the semantic base_link is now expressed directly as
    a normal URDF constant.

    STRICT BOUNDARY:
      * DO NOT re-introduce urdf_shift_* or a second hidden compensation layer
        in TF publishers, sensor extrinsics, MPC/WBC kinematics, Python config,
        or controller code.
      * base_offset_joint remains non-identity on purpose: it places the
        semantic base_link relative to base_footprint while preserving the
        current semantic base definition.

    MAINTENANCE RULE:
      If base_footprint/base_link placement is intentionally redefined in the
      future, update the explicit base_offset_joint constants below and
      re-baseline the guardrails and stand-geometry golden.
  -->
  <xacro:property name="base_offset_x" value="0.2492"/>
  <xacro:property name="base_offset_y" value="0.12503"/>
  <xacro:property name="base_offset_z" value="-0.2649"/>
  <!--
    Semantic trunk root definition
    ============================================================
    base_link is intentionally redefined as the control / dynamics / leg-install
    root near the geometric center of the four leg mounts. It is not required to
    coincide with the CAD shell origin.

    base_link_cad_fixed therefore carries the shell offset, while leg mounts,
    trunk inertial, and trunk collision are all re-expressed in this semantic
    base_link frame.
  -->
  <xacro:property name="base_link_semantic_origin_x" value="0.248975"/>
  <xacro:property name="base_link_semantic_origin_y" value="0.122500"/>
  <xacro:property name="base_link_semantic_origin_z" value="0.0"/>
  <!-- Conservative trunk collision box derived from the legacy collision mesh bbox.
       The upper ~1/3 is trimmed away while keeping the lower envelope unchanged. -->
  <xacro:property name="trunk_collision_box_xyz"
                  value="${0.243115 - base_link_semantic_origin_x} ${0.122499 - base_link_semantic_origin_y} ${-0.006837 - base_link_semantic_origin_z}"/>
  <xacro:property name="trunk_collision_box_size" value="0.342 0.160 0.100333"/>

  <joint name="base_offset_joint" type="fixed">
    <parent link="base_footprint"/>
    <child link="base_link"/>
    <origin xyz="${base_offset_x} ${base_offset_y} ${base_offset_z}" rpy="0 0 ${PI_CONST}"/>
  </joint>

  <!--
    Dual-base scaffold (migration):
      base_link        = ROS / control / Pinocchio root frame (X front, Y left, Z up),
                         now carrying trunk inertial + collision.
      base_link_cad    = CAD trunk visual carrier; leg mounts parent = base_link.
      base_link_cad_fixed = fixed shell offset from the semantic trunk root.
    NOTE:
      Stage 4 (current): base_link has been formally redefined around the
      leg-mount centroid. base_link_cad is now a pure shell carrier attached
      through a non-identity fixed transform.
  -->
  <link name="base_link">
    <inertial>
      <origin xyz="${0.2492 - base_link_semantic_origin_x} ${0.12503 - base_link_semantic_origin_y} ${0.0 - base_link_semantic_origin_z}" rpy="${half_pi} 0 0"/>
      <mass value="6.0"/>
      <inertia ixx="0.0153" ixy="0.00011" ixz="0" iyy="0.052" iyz="0" izz="0.044"/>
    </inertial>
    <collision>
      <origin xyz="${trunk_collision_box_xyz}" rpy="0 0 0"/>
      <geometry>
        <box size="${trunk_collision_box_size}"/>
      </geometry>
    </collision>
  </link>

  <joint name="base_link_cad_fixed" type="fixed">
    <parent link="base_link"/>
    <child link="base_link_cad"/>
    <origin xyz="${0.0 - base_link_semantic_origin_x} ${0.0 - base_link_semantic_origin_y} ${0.0 - base_link_semantic_origin_z}" rpy="0 0 0"/>
  </joint>

  <link name="base_link_cad">
    <visual>
      <origin xyz="-0.9780 0.87203 -0.2649" rpy="0 0 0"/>
      <geometry>
        <mesh filename="package://dog2_description/meshes/base_link.STL"/>
      </geometry>
      <material name="mat_base_gray">
        <color rgba="0.752941176470588 0.752941176470588 0.752941176470588 1"/>
      </material>
    </visual>
  </link>

  <xacro:property name="l1_inertia_xyz" value="-0.0159999123716776 0.000737036465389251 0.0261570925915838"/>
  <xacro:property name="l2_inertia_xyz" value="0.0159999123716776 0.000737036465389251 0.0261570925915838"/>
  <xacro:property name="l3_inertia_xyz" value="-0.0159999123716776 0.000737036465389251 0.0261570925915838"/>
  <xacro:property name="l4_inertia_xyz" value="0.0159999123716776 0.000737036465389251 0.0261570925915838"/>

  <!--
    ========================================================================
    Leg kinematic contract (single source of truth for topology semantics)
    ========================================================================

    Family: **1P + 3R** redundant leg — prismatic rail on the body plus a
    classic **Yaw–Pitch–Pitch** (spider / insect–like) chain in 3D.

    Kinematic shorthand: **P – R_z – R_y – R_y** (mixed / redundant leg).

    **base_link** (REP-103: X forward, Y left, Z up) — *effective* motion
    directions for positive joint coordinates after composing each joint’s
    fixed origin and local axis xyz (validated by
    dog2_description/scripts/check_joint_semantics.py):

    rail_joint:  body slide, semantic axis in base_link +X (forward); local
                 axis xyz may be mirrored per leg so R_rail*axis = +X.
    coxa_joint:  hip yaw sweep, semantic axis vertical (Z class, sign per leg).
    femur_joint: thigh pitch, semantic axis lateral (Y class).
    tibia_joint: knee pitch, axis parallel to femur in nominal pose.

    URDF axis vectors below are expressed in each joint’s URDF joint
    frame (child link at q=0); they are **not** raw base_link tuples. The
    bullet list above is what controllers, Pinocchio, and
    dog2_motion_control/dog2_motion_control/joint_semantics.py must match.

    **Do not** reintroduce a second global CAD shift beyond
    `base_offset_joint`; see the semantic base placement comment above.

    ========================================================================
  -->
  <!-- Leg macro -->
  <xacro:macro name="leg" params="prefix leg_num parent_link rail_axis p_low p_up thigh_xyz shin_xyz slider_inertia_xyz foot_tip_xyz
                                 hip_rpy:='0 0 ${half_pi}' hip_xyz:='-0.016 0.0199 0.055'
                                 knee_xyz:='-0.0233 -0.055 0.0274'
                                 thigh_rpy:='0 0 0' thigh_col_rpy:='0 0 0'">

  <link name="${prefix}_rail_link">
    <inertial>
      <origin rpy="0 0 0" xyz="${slider_inertia_xyz}"/>
      <mass value="0.3"/>
      <inertia ixx="0.0001071" ixy="0" ixz="0" iyy="8.386e-05" iyz="0" izz="7.869e-05"/>
    </inertial>
    <visual>
      <geometry>
        <mesh filename="package://dog2_description/meshes/l${leg_num}.STL"/>
      </geometry>
      <material name="mat_white"><color rgba="1 1 1 1"/></material>
    </visual>
    <collision>
      <geometry>
        <mesh filename="package://dog2_description/meshes/collision/l${leg_num}_collision.STL"/>
      </geometry>
    </collision>
  </link>

  <joint name="${prefix}_rail_joint" type="prismatic">
    <origin rpy="0 0 0" xyz="0 0 0"/>
    <parent link="${parent_link}"/>
    <child link="${prefix}_rail_link"/>
    <!-- +q translates along base_link +X (see kinematic contract block above). -->
    <axis xyz="${rail_axis}"/>
    <limit effort="${prismatic_effort}" lower="${p_low}" upper="${p_up}" velocity="${prismatic_velocity}"/>
    <dynamics damping="${prismatic_damping}" friction="${prismatic_friction}"/>
  </joint>

  <link name="${prefix}_coxa_link">
    <inertial>
      <origin rpy="0 0 0" xyz="-0.0233 -0.0383 0.000879"/>
      <mass value="0.25"/>
      <inertia ixx="0.0001" ixy="0" ixz="0" iyy="0.0001" iyz="0" izz="0.0001"/>
    </inertial>
    <visual>
      <geometry>
        <mesh filename="package://dog2_description/meshes/l${leg_num}1.STL"/>
      </geometry>
      <material name="mat_blue"><color rgba="0.266 0.529 1 1"/></material>
    </visual>
    <collision>
      <geometry>
        <mesh filename="package://dog2_description/meshes/collision/l${leg_num}1_collision.STL"/>
      </geometry>
    </collision>
  </link>

  <joint name="${prefix}_coxa_joint" type="revolute">
    <origin rpy="${hip_rpy}" xyz="${hip_xyz}"/>
    <parent link="${prefix}_rail_link"/>
    <child link="${prefix}_coxa_link"/>
    <axis xyz="-1 0 0"/>
    <limit effort="${hip_effort}" lower="${hip_lower_limit}" upper="${hip_upper_limit}" velocity="${hip_velocity}"/>
    <dynamics damping="${hip_damping}" friction="${hip_friction}"/>
  </joint>

  <link name="${prefix}_femur_link">
    <inertial>
      <origin rpy="0 0 0" xyz="${thigh_xyz}"/>
      <mass value="0.4"/>
      <inertia ixx="0.000666" ixy="0" ixz="0" iyy="0.000356" iyz="0.000266" izz="0.000534"/>
    </inertial>
    <visual>
      <origin rpy="${thigh_rpy}" xyz="0 0 0"/>
      <geometry>
        <mesh filename="package://dog2_description/meshes/l${leg_num}11.STL"/>
      </geometry>
      <material name="mat_white"><color rgba="1 1 1 1"/></material>
    </visual>
    <collision>
      <origin rpy="${thigh_col_rpy}" xyz="0 0 0"/>
      <geometry>
        <mesh filename="package://dog2_description/meshes/collision/l${leg_num}11_collision.STL"/>
      </geometry>
    </collision>
  </link>

  <joint name="${prefix}_femur_joint" type="revolute">
    <origin rpy="${half_pi} ${half_pi} 0" xyz="${knee_xyz}"/>
    <parent link="${prefix}_coxa_link"/>
    <child link="${prefix}_femur_link"/>
    <axis xyz="-1 0 0"/>
    <limit effort="${knee_effort}" lower="${knee_lower_limit}" upper="${knee_upper_limit}" velocity="${knee_velocity}"/>
    <dynamics damping="${knee_damping}" friction="${knee_friction}"/>
  </joint>

  <link name="${prefix}_tibia_link">
    <inertial>
      <origin rpy="0 0 0" xyz="${shin_xyz}"/>
      <mass value="0.5"/>
      <inertia ixx="0.004517" ixy="0.0000087" ixz="0.0000042" iyy="0.000975" iyz="-0.001769" izz="0.003666"/>
    </inertial>
    <visual>
      <geometry>
        <mesh filename="package://dog2_description/meshes/l${leg_num}111.STL"/>
      </geometry>
      <material name="mat_white"><color rgba="1 1 1 1"/></material>
    </visual>
    <collision>
      <geometry>
        <mesh filename="package://dog2_description/meshes/collision/l${leg_num}111_collision.STL"/>
      </geometry>
    </collision>
  </link>

  <joint name="${prefix}_tibia_joint" type="revolute">
    <origin rpy="0 0 0" xyz="0 -0.15201 0.12997"/>
    <parent link="${prefix}_femur_link"/>
    <child link="${prefix}_tibia_link"/>
    <axis xyz="-1 0 0"/>
    <limit effort="${knee_effort}" lower="${knee_lower_limit}" upper="${knee_upper_limit}" velocity="${knee_velocity}"/>
    <dynamics damping="${knee_damping}" friction="${knee_friction}"/>
  </joint>

  <joint name="${prefix}_foot_fixed" type="fixed">
    <origin rpy="0 0 0" xyz="${foot_tip_xyz}"/>
    <parent link="${prefix}_tibia_link"/>
    <child link="${prefix}_foot_link"/>
  </joint>

  <!-- foot_link: 足端 frame 原点 = 球心；collision 与 visual 同球（r=foot_sphere_radius）。 -->
  <link name="${prefix}_foot_link">
    <inertial>
      <origin rpy="0 0 0" xyz="0 0 0"/>
      <mass value="0.05"/>
      <inertia ixx="2.88e-06" ixy="0" ixz="0" iyy="2.88e-06" iyz="0" izz="2.88e-06"/>
    </inertial>
    <visual>
      <origin rpy="0 0 0" xyz="0 0 0"/>
      <geometry>
        <sphere radius="${foot_sphere_radius}"/>
      </geometry>
      <material name="mat_foot_debug"><color rgba="0.2 0.85 0.35 1"/></material>
    </visual>
    <collision>
      <origin rpy="0 0 0" xyz="0 0 0"/>
      <geometry>
        <sphere radius="${foot_sphere_radius}"/>
      </geometry>
    </collision>
  </link>

  <!-- 胫骨原语若蹭地：低刚度/低摩擦，主触地仍由 foot 球承担。 -->
  <gazebo reference="${prefix}_tibia_link">
    <mu1>0.05</mu1>
    <mu2>0.05</mu2>
    <kp>800</kp>
    <kd>8</kd>
    <minDepth>${foot_contact_min_depth}</minDepth>
    <maxVel>${foot_contact_max_vel}</maxVel>
  </gazebo>

  <gazebo reference="${prefix}_foot_link">
    <mu1>${foot_contact_mu1}</mu1>
    <mu2>${foot_contact_mu2}</mu2>
    <kp>${foot_contact_kp}</kp>
    <kd>${foot_contact_kd}</kd>
    <minDepth>${foot_contact_min_depth}</minDepth>
    <maxVel>${foot_contact_max_vel}</maxVel>
    <material>Gazebo/Grey</material>
    <sensor name="${prefix}_foot_contact" type="contact">
      <always_on>true</always_on>
      <update_rate>200</update_rate>
      <contact/>
    </sensor>
  </gazebo>

  </xacro:macro>

  <!-- Leg instantiations -->
  <!--
    *_leg_mount is the fixed installation frame of each leg relative to base_link.
    left/right/front/rear differences should be expressed here.
    The leg macro below represents a reusable standard leg chain.

    Leg topology reminder (base_link-local installation frames):
      - lf: left front  (左前)
      - lh: left rear   (左后)
      - rh: right rear  (右后)
      - rf: right front (右前)
  -->
  <link name="lf_leg_mount"/>
  <joint name="lf_leg_mount_fixed" type="fixed">
    <parent link="base_link"/>
    <child link="lf_leg_mount"/>
    <origin xyz="${0.1246 - base_link_semantic_origin_x} ${0.0625 - base_link_semantic_origin_y} ${0.0 - base_link_semantic_origin_z}" rpy="${leg_rail_rpy_L}"/>
  </joint>

  <link name="lh_leg_mount"/>
  <joint name="lh_leg_mount_fixed" type="fixed">
    <parent link="base_link"/>
    <child link="lh_leg_mount"/>
    <origin xyz="${0.3711 - base_link_semantic_origin_x} ${0.0625 - base_link_semantic_origin_y} ${0.0 - base_link_semantic_origin_z}" rpy="${leg_rail_rpy_L}"/>
  </joint>

  <link name="rh_leg_mount"/>
  <joint name="rh_leg_mount_fixed" type="fixed">
    <parent link="base_link"/>
    <child link="rh_leg_mount"/>
    <origin xyz="${0.3711 - base_link_semantic_origin_x} ${0.1825 - base_link_semantic_origin_y} ${0.0 - base_link_semantic_origin_z}" rpy="${leg_rail_rpy_R}"/>
  </joint>

  <link name="rf_leg_mount"/>
  <joint name="rf_leg_mount_fixed" type="fixed">
    <parent link="base_link"/>
    <child link="rf_leg_mount"/>
    <origin xyz="${0.1291 - base_link_semantic_origin_x} ${0.1825 - base_link_semantic_origin_y} ${0.0 - base_link_semantic_origin_z}" rpy="${leg_rail_rpy_R}"/>
  </joint>

  <!-- Leg 1: Front Left (lf) via lf_leg_mount -->
  <xacro:leg prefix="lf" leg_num="1" parent_link="lf_leg_mount" rail_axis="${leg_rail_axis_L}" p_low="0.0" p_up="0.111"
             thigh_xyz="${leg12_thigh_xyz}" shin_xyz="${leg12_shin_xyz}" slider_inertia_xyz="${l1_inertia_xyz}"
             foot_tip_xyz="${leg12_foot_tip_xyz}"/>

  <!-- Leg 2: Rear Left (lh) via lh_leg_mount -->
  <xacro:leg prefix="lh" leg_num="2" parent_link="lh_leg_mount" rail_axis="${leg_rail_axis_L}" p_low="-0.111" p_up="0.0"
             thigh_xyz="${leg12_thigh_xyz}" shin_xyz="${leg12_shin_xyz}" slider_inertia_xyz="${l2_inertia_xyz}"
             hip_xyz="0.016 0.0199 0.055"
             foot_tip_xyz="${leg12_foot_tip_xyz}"/>

  <!-- Leg 3: Rear Right (rh) via rh_leg_mount -->
  <xacro:leg prefix="rh" leg_num="3" parent_link="rh_leg_mount" rail_axis="${leg_rail_axis_R}" p_low="0.0" p_up="0.111"
             thigh_xyz="${leg3_thigh_xyz}" shin_xyz="${leg3_shin_xyz}" slider_inertia_xyz="${l3_inertia_xyz}"
             hip_rpy="${leg_hip_rpy_R}" knee_xyz="${leg_knee_xyz_R}"
             foot_tip_xyz="${leg3_foot_tip_xyz}"/>

  <!-- Leg 4: Front Right (rf) via rf_leg_mount -->
  <xacro:leg prefix="rf" leg_num="4" parent_link="rf_leg_mount" rail_axis="${leg_rail_axis_R}" p_low="-0.111" p_up="0.0"
             thigh_xyz="${leg4_thigh_xyz}" shin_xyz="${leg4_shin_xyz}" slider_inertia_xyz="${l4_inertia_xyz}"
             hip_rpy="${leg_hip_rpy_R}" hip_xyz="0.0116 0.0199 0.055" knee_xyz="${leg_knee_xyz_R}"
             thigh_rpy="${leg_thigh_mesh_flip_rpy}" thigh_col_rpy="${leg_thigh_mesh_flip_rpy}"
             foot_tip_xyz="${leg4_foot_tip_xyz}"/>

  <!-- ROS 2 Control -->
  <ros2_control name="GazeboSimSystem" type="system">
    <hardware>
      <plugin>gz_ros2_control/GazeboSimSystem</plugin>
    </hardware>
    <joint name="lf_rail_joint">
      <command_interface name="position"/>
      <command_interface name="effort"/>
      <state_interface name="position"/>
      <state_interface name="velocity"/>
    </joint>
    <joint name="lf_coxa_joint">
      <command_interface name="position"/>
      <command_interface name="effort"/>
      <state_interface name="position"/>
      <state_interface name="velocity"/>
    </joint>
    <joint name="lf_femur_joint">
      <command_interface name="position"/>
      <command_interface name="effort"/>
      <state_interface name="position"/>
      <state_interface name="velocity"/>
    </joint>
    <joint name="lf_tibia_joint">
      <command_interface name="position"/>
      <command_interface name="effort"/>
      <state_interface name="position"/>
      <state_interface name="velocity"/>
    </joint>
    <joint name="lh_rail_joint">
      <command_interface name="position"/>
      <command_interface name="effort"/>
      <state_interface name="position"/>
      <state_interface name="velocity"/>
    </joint>
    <joint name="lh_coxa_joint">
      <command_interface name="position"/>
      <command_interface name="effort"/>
      <state_interface name="position"/>
      <state_interface name="velocity"/>
    </joint>
    <joint name="lh_femur_joint">
      <command_interface name="position"/>
      <command_interface name="effort"/>
      <state_interface name="position"/>
      <state_interface name="velocity"/>
    </joint>
    <joint name="lh_tibia_joint">
      <command_interface name="position"/>
      <command_interface name="effort"/>
      <state_interface name="position"/>
      <state_interface name="velocity"/>
    </joint>
    <joint name="rh_rail_joint">
      <command_interface name="position"/>
      <command_interface name="effort"/>
      <state_interface name="position"/>
      <state_interface name="velocity"/>
    </joint>
    <joint name="rh_coxa_joint">
      <command_interface name="position"/>
      <command_interface name="effort"/>
      <state_interface name="position"/>
      <state_interface name="velocity"/>
    </joint>
    <joint name="rh_femur_joint">
      <command_interface name="position"/>
      <command_interface name="effort"/>
      <state_interface name="position"/>
      <state_interface name="velocity"/>
    </joint>
    <joint name="rh_tibia_joint">
      <command_interface name="position"/>
      <command_interface name="effort"/>
      <state_interface name="position"/>
      <state_interface name="velocity"/>
    </joint>
    <joint name="rf_rail_joint">
      <command_interface name="position"/>
      <command_interface name="effort"/>
      <state_interface name="position"/>
      <state_interface name="velocity"/>
    </joint>
    <joint name="rf_coxa_joint">
      <command_interface name="position"/>
      <command_interface name="effort"/>
      <state_interface name="position"/>
      <state_interface name="velocity"/>
    </joint>
    <joint name="rf_femur_joint">
      <command_interface name="position"/>
      <command_interface name="effort"/>
      <state_interface name="position"/>
      <state_interface name="velocity"/>
    </joint>
    <joint name="rf_tibia_joint">
      <command_interface name="position"/>
      <command_interface name="effort"/>
      <state_interface name="position"/>
      <state_interface name="velocity"/>
    </joint>
  </ros2_control>

  <gazebo>
    <plugin filename="libgz_ros2_control-system.so" name="gz_ros2_control::GazeboSimROS2ControlPlugin">
      <parameters>${controllers_yaml}</parameters>
      <robot_param>robot_description</robot_param>
      <robot_param_node>robot_state_publisher</robot_param_node>
    </plugin>
  </gazebo>

</robot>
